Workbook

Sheet Brief Intro

Sheet colleges Cleaned
A1: date | B1: state | C1: county | D1: city | E1: ipeds_id | F1: college | G1: cases | H1: cases_2021 | I1: notes
A2: 44342 | B2: Alabama | C2: Madison | D2: Huntsville | E2: 100654 | F2: Alabama A&M University | G2: 41
A3: 44342 | B3: Alabama | C3: Montgomery | D3: Montgomery | E3: 100724 | F3: Alabama State University | G3: 2
A4: 44342 | B4: Alabama | C4: Limestone | D4: Athens | E4: 100812 | F4: Athens State University | G4: 45 | H4: 10
A5: 44342 | B5: Alabama | C5: Lee | D5: Auburn | E5: 100858 | F5: Auburn University | G5: 2742 | H5: 567
A6: 44342 | B6: Alabama | C6: Montgomery | D6: Montgomery | E6: 100830 | F6: Auburn University at Montgomery | G6: 220 | H6: 80
A7: 44342 | B7: Alabama | C7: Walker | D7: Jasper | E7: 102429 | F7: Bevill State Community College | G7: 4
A8: 44342 | B8: Alabama | C8: Jefferson | D8: Birmingham | E8: 100937 | F8: Birmingham-Southern College | G8: 263 | H8: 49
A9: 44342 | B9: Alabama | C9: Limestone | D9: Tanner | E9: 101514 | F9: Calhoun Community College | G9: 137 | H9: 53
A10: 44342 | B10: Alabama | C10: Tallapoosa | D10: Alexander City | E10: 100760 | F10: Central Alabama Community College | G10: 49 | H10: 10
A11: 44342 | B11: Alabama | C11: Coffee | D11: Enterprise | E11: 101143 | F11: Enterprise State Community College | G11: 76 | H11: 35
A12: 44342 | B12: Alabama | C12: Etowah | D12: Gadsden | E12: 101240 | F12: Gadsden State Community College | G12: 67 | H12: 5
A13: 44342 | B13: Alabama | C13: Montgomery | D13: Montgomery | E13: 101435 | F13: Huntingdon College | G13: 0
A14: 44342 | B14: Alabama | C14: Calhoun | D14: Jacksonville | E14: 101480 | F14: Jacksonville State University | G14: 229 | H14: 10
A15: 44342 | B15: Alabama | C15: Covington | D15: Andalusia | E15: 101602 | F15: Lurleen B. Wallace Community College | G15: 19
A16: 44342 | B16: Alabama | C16: Perry | D16: Marion | E16: 101648 | F16: Marion Military Institute | G16: 45 | H16: 19
A17: 44342 | B17: Alabama | C17: Jefferson | D17: Fairfield | E17: 101675 | F17: Miles College | G17: 0
A18: 44342 | B18: Alabama | C18: Jefferson | D18: Birmingham | E18: 102049 | F18: Samford University | G18: 666 | H18: 186
A19: 44342 | B19: Alabama | C19: Marshall | D19: Boaz | E19: 102076 | F19: Snead State Community College | G19: 29 | H19: 10
A20: 44342 | B20: Alabama | C20: Randolph | D20: Wadley | E20: 251260 | F20: Southern Union State Community College | G20: 295 | H20: 78
A21: 44342 | B21: Alabama | C21: Mobile | D21: Mobile | E21: 102234 | F21: Spring Hill College | G21: 162 | H21: 38
A22: 44342 | B22: Alabama | C22: Pike | D22: Troy | E22: 102368 | F22: Troy University | G22: 855 | H22: 106
A23: 44342 | B23: Alabama | C23: Houston | D23: Dothan | E23: 10236803 | F23: Troy University Dothan | G23: 18 | H23: 1
A24: 44342 | B24: Alabama | C24: Montgomery | D24: Montgomery | E24: 10236802 | F24: Troy University Montgomery | G24: 20 | H24: 2
A25: 44342 | B25: Alabama | C25: Russell | D25: Phenix | E25: 10236801 | F25: Troy University Phenix City | G25: 10 | H25: 1
A26: 44342 | B26: Alabama | C26: Macon | D26: Tuskeegee | E26: 102377 | F26: Tuskegee University | G26: 110
A27: 44342 | B27: Alabama | C27: Tuscaloosa | D27: Tuscaloosa | E27: 100751 | F27: University of Alabama | G27: 4565 | H27: 1204
A28: 44342 | B28: Alabama | C28: Jefferson | D28: Birmingham | E28: 100663 | F28: University of Alabama at Birmingham | G28: 3143 | H28: 857 | I28: Total is known to include one or more cases from a medical school, medical center, teaching hospital, clinical setting or other academic program in health sciences.
A29: 44342 | B29: Alabama | C29: Madison | D29: Huntsville | E29: 100706 | F29: University of Alabama in Huntsville | G29: 393 | H29: 183
A30: 44342 | B30: Alabama | C30: Shelby | D30: Montevallo | E30: 101709 | F30: University of Montevallo | G30: 192 | H30: 52
A31: 44342 | B31: Alabama | C31: Lauderdale | D31: Florence | E31: 101879 | F31: University of North Alabama | G31: 763 | H31: 275
A32: 44342 | B32: Alabama | C32: Mobile | D32: Mobile | E32: 102094 | F32: University of South Alabama | G32: 780 | H32: 273
A33: 44342 | B33: Alabama | C33: Sumter | D33: Livingston | E33: 101587 | F33: University of West Alabama | G33: 35 | H33: 5 | I33: College did not clarify whether data includes duplicate cases.
A34: 44342 | B34: Alaska | C34: North Slope Borough | D34: Utqiagvik | E34: 434584 | F34: Ilisagvik College | G34: 0
A35: 44342 | B35: Alaska | C35: Anchorage Municipality | D35: Anchorage | E35: 102553 | F35: University of Alaska Anchorage | G35: 186 | H35: 51
A36: 44342 | B36: Alaska | C36: Fairbanks North Star Borough | D36: Fairbanks | E36: 102614 | F36: University of Alaska Fairbanks | G36: 228 | H36: 79
A37: 44342 | B37: Alaska | C37: Juneau City and Borough | D37: Juneau | E37: 102632 | F37: University of Alaska Southeast | G37: 16 | H37: 3
A38: 44342 | B38: American Samoa | C38: Maoputasi | D38: Pago Pago | E38: 240736 | F38: American Samoa Community College | G38: 0 | H38: 0
A39: 44342 | B39: Arizona | C39: Maricopa | D39: Tempe | E39: 104151 | F39: Arizona State University | G39: 6766 | H39: 2261
A40: 44342 | B40: Arizona | C40: Yuma | D40: Yuma | E40: 104160 | F40: Arizona Western College | G40: 41
...

Sheet Cleaned Data 
A1: date | B1: state | C1: county | D1: city | F1: college | G1: cases | H1: cases_2021 | I1: notes
A2: 44342 | B2: Alabama | C2: Madison | D2: Huntsville | E2: 100654 | F2: Alabama A&M University | G2: 41 | H2: NA | I2: NA
A3: 44342 | B3: Alabama | C3: Montgomery | D3: Montgomery | E3: 100724 | F3: Alabama State University | G3: 2 | H3: NA | I3: NA
A4: 44342 | B4: Alabama | C4: Limestone | D4: Athens | E4: 100812 | F4: Athens State University | G4: 45 | H4: 10 | I4: NA
A5: 44342 | B5: Alabama | C5: Lee | D5: Auburn | E5: 100858 | F5: Auburn University | G5: 2742 | H5: 567 | I5: NA | M5: AVERAGE | N5: 2020
A6: 44342 | B6: Alabama | C6: Montgomery | D6: Montgomery | E6: 100830 | F6: Auburn University at Montgomery | G6: 220 | H6: 80 | I6: NA | M6: College | N6: =AVERAGE(Table1[cases]) -> 363.5385
A7: 44342 | B7: Alabama | C7: Walker | D7: Jasper | E7: 102429 | F7: Bevill State Community College | G7: 4 | H7: NA | I7: NA
A8: 44342 | B8: Alabama | C8: Jefferson | D8: Birmingham | E8: 100937 | F8: Birmingham-Southern College | G8: 263 | H8: 49 | I8: NA
A9: 44342 | B9: Alabama | C9: Limestone | D9: Tanner | E9: 101514 | F9: Calhoun Community College | G9: 137 | H9: 53 | I9: NA | M9: AVERAGE
A10: 44342 | B10: Alabama | C10: Tallapoosa | D10: Alexander City | E10: 100760 | F10: Central Alabama Community College | G10: 49 | H10: 10 | I10: NA
A11: 44342 | B11: Alabama | C11: Coffee | D11: Enterprise | E11: 101143 | F11: Enterprise State Community College | G11: 76 | H11: 35 | I11: NA
A12: 44342 | B12: Alabama | C12: Etowah | D12: Gadsden | E12: 101240 | F12: Gadsden State Community College | G12: 67 | H12: 5 | I12: NA
A13: 44342 | B13: Alabama | C13: Montgomery | D13: Montgomery | E13: 101435 | F13: Huntingdon College | G13: 0 | H13: NA | I13: NA
A14: 44342 | B14: Alabama | C14: Calhoun | D14: Jacksonville | E14: 101480 | F14: Jacksonville State University | G14: 229 | H14: 10 | I14: NA
A15: 44342 | B15: Alabama | C15: Covington | D15: Andalusia | E15: 101602 | F15: Lurleen B. Wallace Community College | G15: 19 | H15: NA | I15: NA
A16: 44342 | B16: Alabama | C16: Perry | D16: Marion | E16: 101648 | F16: Marion Military Institute | G16: 45 | H16: 19 | I16: NA
A17: 44342 | B17: Alabama | C17: Jefferson | D17: Fairfield | E17: 101675 | F17: Miles College | G17: 0 | H17: NA | I17: NA
A18: 44342 | B18: Alabama | C18: Jefferson | D18: Birmingham | E18: 102049 | F18: Samford University | G18: 666 | H18: 186 | I18: NA
A19: 44342 | B19: Alabama | C19: Marshall | D19: Boaz | E19: 102076 | F19: Snead State Community College | G19: 29 | H19: 10 | I19: NA
A20: 44342 | B20: Alabama | C20: Randolph | D20: Wadley | E20: 251260 | F20: Southern Union State Community College | G20: 295 | H20: 78 | I20: NA
A21: 44342 | B21: Alabama | C21: Mobile | D21: Mobile | E21: 102234 | F21: Spring Hill College | G21: 162 | H21: 38 | I21: NA
A22: 44342 | B22: Alabama | C22: Pike | D22: Troy | E22: 102368 | F22: Troy University | G22: 855 | H22: 106 | I22: NA
A23: 44342 | B23: Alabama | C23: Houston | D23: Dothan | E23: 10236803 | F23: Troy University Dothan | G23: 18 | H23: 1 | I23: NA
A24: 44342 | B24: Alabama | C24: Montgomery | D24: Montgomery | E24: 10236802 | F24: Troy University Montgomery | G24: 20 | H24: 2 | I24: NA
A25: 44342 | B25: Alabama | C25: Russell | D25: Phenix | E25: 10236801 | F25: Troy University Phenix City | G25: 10 | H25: 1 | I25: NA
A26: 44342 | B26: Alabama | C26: Macon | D26: Tuskeegee | E26: 102377 | F26: Tuskegee University | G26: 110 | H26: NA | I26: NA
A27: 44342 | B27: Alabama | C27: Tuscaloosa | D27: Tuscaloosa | E27: 100751 | F27: University of Alabama | G27: 4565 | H27: 1204 | I27: NA
A28: 44342 | B28: Alabama | C28: Jefferson | D28: Birmingham | E28: 100663 | F28: University of Alabama at Birmingham | G28: 3143 | H28: 857 | I28: Total is known to include one or more cases from a medical school, medical center, teaching hospital, clinical setting or other academic program in health sciences.
A29: 44342 | B29: Alabama | C29: Madison | D29: Huntsville | E29: 100706 | F29: University of Alabama in Huntsville | G29: 393 | H29: 183 | I29: NA
A30: 44342 | B30: Alabama | C30: Shelby | D30: Montevallo | E30: 101709 | F30: University of Montevallo | G30: 192 | H30: 52 | I30: NA
A31: 44342 | B31: Alabama | C31: Lauderdale | D31: Florence | E31: 101879 | F31: University of North Alabama | G31: 763 | H31: 275 | I31: NA
A32: 44342 | B32: Alabama | C32: Mobile | D32: Mobile | E32: 102094 | F32: University of South Alabama | G32: 780 | H32: 273 | I32: NA
A33: 44342 | B33: Alabama | C33: Sumter | D33: Livingston | E33: 101587 | F33: University of West Alabama | G33: 35 | H33: 5 | I33: College did not clarify whether data includes duplicate cases.
A34: 44342 | B34: Alaska | C34: North Slope Borough | D34: Utqiagvik | E34: 434584 | F34: Ilisagvik College | G34: 0 | H34: NA | I34: NA
A35: 44342 | B35: Alaska | C35: Anchorage Municipality | D35: Anchorage | E35: 102553 | F35: University of Alaska Anchorage | G35: 186 | H35: 51 | I35: NA
A36: 44342 | B36: Alaska | C36: Fairbanks North Star Borough | D36: Fairbanks | E36: 102614 | F36: University of Alaska Fairbanks | G36: 228 | H36: 79 | I36: NA
A37: 44342 | B37: Alaska | C37: Juneau City and Borough | D37: Juneau | E37: 102632 | F37: University of Alaska Southeast | G37: 16 | H37: 3 | I37: NA
A38: 44342 | B38: American Samoa | C38: Maoputasi | D38: Pago Pago | E38: 240736 | F38: American Samoa Community College | G38: 0 | H38: 0 | I38: NA
A39: 44342 | B39: Arizona | C39: Maricopa | D39: Tempe | E39: 104151 | F39: Arizona State University | G39: 6766 | H39: 2261 | I39: NA
A40: 44342 | B40: Arizona | C40: Yuma | D40: Yuma | E40: 104160 | F40: Arizona Western College | G40: 41 | H40: NA | I40: NA
...

Sheet Analysis PivotTable
A2: Cases By University 2020 | E2: Cases by State 2020 | H2: Cases by county 2020 | K2: College cases 2021 | O2: State total cases in 2021 | S2: County cases 2021 | Z2: Year -to -Year Cases by City | AF2: Year -to -Year Cases by College | AL2: Year -to -Year Cases by County | BB2: Year -to -Year Cases by State
A3: Row Labels | B3: College Cases | E3: Row Labels | F3: Total by State | H3: Row Labels | I3: County Cases | K3: Row Labels | L3: Colleges Cases 2021 | O3: Row Labels | P3: State Total cases 2021 | S3: Row Labels | T3: Cases County 2021 | W3: Total cases 2021 | X3: 2020 Total cases | Z3: Row Labels | AA3: 2020 cases | AB3: 2021 cases | AF3: Row Labels | AG3: 2020 cases | AH3: 2021 cases | AL3: Row Labels | AM3: 2020 cases | AN3: 2021 cases | AT3: Row Labels | BB3: Row Labels | BC3: 2020 cases | BD3: 2021 cases
A4: Abilene Christian University | B4: 773 | E4: Alabama | F4: 15975 | H4: Abbeville | I4: 0 | K4: Abilene Christian University | L4: 163 | O4: Alabama | P4: 4109 | S4: Abbeville | T4: 0 | W4: 270827 | X4: 708173 | Z4: Aberdeen | AA4: 180 | AB4: 5 | AF4: Abilene Christian University | AG4: 773 | AH4: 163 | AL4: Abbeville | AM4: 0 | AN4: 0 | AT4: 100654 | BB4: Alabama | BC4: 15975 | BD4: 4109 | BK4: AVERAGE | BL4: 2020 | BO4: $BK4:$BL4
A5: Abraham Baldwin Agricultural College | B5: 267 | E5: Alaska | F5: 430 | H5: Acadia | I5: 149 | K5: Abraham Baldwin Agricultural College | L5: 102 | O5: Alaska | P5: 133 | S5: Acadia | T5: 76 | Z5: Abilene | AA5: 988 | AB5: 214 | AF5: Abraham Baldwin Agricultural College | AG5: 267 | AH5: 102 | AL5: Acadia | AM5: 149 | AN5: 76 | AT5: 100663 | BB5: Alaska | BC5: 430 | BD5: 133 | BK5: Alabama | BL5: =AVERAGEIF(Table1[#All],BK10,'Cleaned Data '!G:G) -> 137.34667
A6: Academy of Art University | B6: 0 | E6: American Samoa | F6: 0 | H6: Ada | I6: 1642 | K6: Academy of Art University | L6: 0 | O6: American Samoa | P6: 0 | S6: Ada | T6: 517 | Z6: Abingdon | AA6: 4 | AB6: 0 | AF6: Academy of Art University | AG6: 0 | AH6: 0 | AL6: Ada | AM6: 1642 | AN6: 517 | AT6: 100706 | BB6: American Samoa | BC6: 0 | BD6: 0 | BK6: Alaska | BL6: =AVERAGEIF(Table1[#All],BK6,'Cleaned Data '!G:G) -> 44.333333
A7: Adams State University | B7: 176 | E7: Arizona | F7: 16419 | H7: Adair | I7: 749 | K7: Adams State University | L7: 68 | O7: Arizona | P7: 5440 | S7: Adair | T7: 318 | Z7: Abington | AA7: 57 | AB7: 28 | AF7: Adams State University | AG7: 176 | AH7: 68 | AL7: Adair | AM7: 749 | AN7: 318 | AT7: 100724 | BB7: Arizona | BC7: 16419 | BD7: 5440 | BK7: American Samoa | BL7: =AVERAGEIF(Table1[#All],BK7,'Cleaned Data '!G:G) -> 0
A8: Adelphi University | B8: 231 | E8: Arkansas | F8: 10675 | H8: Adams | I8: 948 | K8: Adelphi University | L8: 171 | O8: Arkansas | P8: 2665 | S8: Adams | T8: 308 | Z8: Ada | AA8: 230 | AB8: 95 | AF8: Adelphi University | AG8: 231 | AH8: 171 | AL8: Adams | AM8: 948 | AN8: 308 | AT8: 100751 | BB8: Arkansas | BC8: 10675 | BD8: 2665 | BK8: Arizona | BL8: =AVERAGEIF(Table1[#All],BK8,'Cleaned Data '!G:G) -> 680
A9: Adirondack Community College | B9: 33 | E9: California | F9: 21668 | H9: Addison | I9: 29 | K9: Adirondack Community College | L9: 25 | O9: California | P9: 10301 | S9: Addison | T9: 22 | Z9: Adrian | AA9: 646 | AB9: 249 | AF9: Adirondack Community College | AG9: 33 | AH9: 25 | AL9: Addison | AM9: 29 | AN9: 22 | AT9: 100760 | BB9: California | BC9: 21668 | BD9: 10301 | BK9: Arkansas | BL9: =AVERAGEIF(Table1[#All],BK9,'Cleaned Data '!G:G) -> 106.6
A10: Adrian College | B10: 484 | E10: Colorado | F10: 14647 | H10: Aguadilla | I10: 0 | K10: Adrian College | L10: 152 | O10: Colorado | P10: 5884 | S10: Aguadilla | T10: 0 | Z10: Aguadilla | AA10: 0 | AB10: 0 | AF10: Adrian College | AG10: 484 | AH10: 152 | AL10: Aguadilla | AM10: 0 | AN10: 0 | AT10: 100812 | BB10: Colorado | BC10: 14647 | BD10: 5884 | BK10: California | BL10: =AVERAGEIF(Table1[#All],BK10,'Cleaned Data '!G:G) -> 137.34667
A11: AdventHealth University | B11: 4 | E11: Connecticut | F11: 8943 | H11: Aiken | I11: 132 | K11: AdventHealth University | L11: 0 | O11: Connecticut | P11: 4358 | S11: Aiken | T11: 45 | Z11: Aiken | AA11: 132 | AB11: 45 | AF11: AdventHealth University | AG11: 4 | AH11: 0 | AL11: Aiken | AM11: 132 | AN11: 45 | AT11: 100830 | BB11: Connecticut | BC11: 8943 | BD11: 4358 | BK11: Colorado | BL11: =AVERAGEIF(Table1[#All],BK11,'Cleaned Data '!G:G) -> 226.30769
A12: Agnes Scott College | B12: 17 | E12: Delaware | F12: 3264 | H12: Alachua | I12: 9986 | K12: Agnes Scott College | L12: 14 | O12: Delaware | P12: 1989 | S12: Alachua | T12: 3205 | Z12: Air Force Academy | AA12: 2 | AB12: 0 | AF12: Agnes Scott College | AG12: 17 | AH12: 14 | AL12: Alachua | AM12: 9986 | AN12: 3205 | AT12: 100858 | BB12: Delaware | BC12: 3264 | BD12: 1989 | BK12: Connecticut | BL12: =AVERAGEIF(Table1[#All],BK12,'Cleaned Data '!G:G) -> 229.36842
A13: Air Force Institute of Technology-Graduate School of Engineering & Management | B13: 0 | E13: Florida | F13: 35499 | H13: Alamance | I13: 1470 | K13: Air Force Institute of Technology-Graduate School of Engineering & Management | L13: 0 | O13: Florida | P13: 13681 | S13: Alamance | T13: 537 | Z13: Akron | AA13: 693 | AB13: 304 | AF13: Air Force Institute of Technology-Graduate School of Engineering & Management | AG13: 0 | AH13: 0 | AL13: Alamance | AM13: 1470 | AN13: 537 | AT13: 100937 | BB13: Florida | BC13: 35499 | BD13: 13681 | BK13: Deleware | BL13: =AVERAGEIF(Table1[#All],BK13,'Cleaned Data '!G:G) -> #DIV/0!
A14: Alabama A&M University | B14: 41 | E14: Georgia | F14: 23235 | H14: Alameda | I14: 1163 | K14: Alabama A&M University | L14: 0 | O14: Georgia | P14: 8413 | S14: Alameda | T14: 708 | Z14: Alamosa | AA14: 176 | AB14: 68 | AF14: Alabama A&M University | AG14: 41 | AH14: 0 | AL14: Alameda | AM14: 1163 | AN14: 708 | AT14: 101143 | BB14: Georgia | BC14: 23235 | BD14: 8413 | BK14: Florida | BL14: =AVERAGEIF(Table1[#All],BK14,'Cleaned Data '!G:G) -> 231.88136
A15: Alabama State University | B15: 2 | E15: Guam | F15: 12 | H15: Alamosa | I15: 176 | K15: Alabama State University | L15: 0 | O15: Guam | P15: 0 | S15: Alamosa | T15: 68 | Z15: Albany | AA15: 1515 | AB15: 795 | AF15: Alabama State University | AG15: 2 | AH15: 0 | AL15: Alamosa | AM15: 176 | AN15: 68 | AT15: 101240 | BB15: Guam | BC15: 12 | BD15: 0 | BK15: Georgia | BL15: =AVERAGEIF(Table1[#All],BK15,'Cleaned Data '!G:G) -> 227.37838
A16: Albany College of Pharmacy and Health Sciences | B16: 57 | E16: Hawaii | F16: 153 | H16: Albany | I16: 3875 | K16: Albany College of Pharmacy and Health Sciences | L16: 36 | O16: Hawaii | P16: 91 | S16: Albany | T16: 1300 | Z16: Albion | AA16: 189 | AB16: 126 | AF16: Albany College of Pharmacy and Health Sciences | AG16: 57 | AH16: 36 | AL16: Albany | AM16: 3875 | AN16: 1300 | AT16: 101435 | BB16: Hawaii | BC16: 153 | BD16: 91 | BK16: Guam | BL16: =AVERAGEIF(Table1[#All],BK16,'Cleaned Data '!G:G) -> #DIV/0!
A17: Albany Medical College | B17: 56 | E17: Idaho | F17: 7570 | H17: Allegany | I17: 874 | K17: Albany Medical College | L17: 31 | O17: Idaho | P17: 2372 | S17: Allegany | T17: 485 | Z17: Albuquerque | AA17: 506 | AB17: 157 | AF17: Albany Medical College | AG17: 56 | AH17: 31 | AL17: Allegany | AM17: 874 | AN17: 485 | AT17: 101480 | BB17: Idaho | BC17: 7570 | BD17: 2372 | BK17: Hawaii | BL17: =AVERAGEIF(Table1[#All],BK17,'Cleaned Data '!G:G) -> 13
... A61: Ashland University | B61: 354 | E61: Grand Total | F61: 708173 | H61: Berkshire | I61: 103 | K61: Ashland University | L61: 203 | O61: Grand Total | P61: 270827 | S61: Berkshire | T61: 74 | Z61: Babson Park | AA61: 31 | AB61: 0 | AF61: Ashland University | AG61: 354 | AH61: 203 | AL61: Berkshire | AM61: 103 | AN61: 74 | AT61: 107460 | BB61: Grand Total | BC61: 708173 | BD61: 270827 | BK61: Wyoming | BL61: =AVERAGEIF(Table1[#All],BK61,'Cleaned Data '!G:G) -> 86.5
A62: Assumption College | B62: 116 | H62: Bernalillo | I62: 506 | K62: Assumption College | L62: 55 | S62: Bernalillo | T62: 157 | Z62: Bakersfield | AA62: 97 | AB62: 29 | AF62: Assumption College | AG62: 116 | AH62: 55 | AL62: Bernalillo | AM62: 506 | AN62: 157 | AT62: 107512
A63: Athens State University | B63: 45 | H63: Berrien | I63: 245 | K63: Athens State University | L63: 10 | S63: Berrien | T63: 122 | Z63: Baldwin City | AA63: 113 | AB63: 3 | AF63: Athens State University | AG63: 45 | AH63: 10 | AL63: Berrien | AM63: 245 | AN63: 122 | AT63: 107558
A64: Atlanta Metropolitan State College | B64: 2 | H64: Bexar | I64: 1490 | K64: Atlanta Metropolitan State College | L64: 2 | S64: Bexar | T64: 414 | Z64: Baltimore | AA64: 1963 | AB64: 1071 | AF64: Atlanta Metropolitan State College | AG64: 2 | AH64: 2 | AL64: Bexar | AM64: 1490 | AN64: 414 | AT64: 107585
A65: Atlantic Technical College | B65: 40 | H65: Bibb | I65: 1180 | K65: Atlantic Technical College | L65: 0 | S65: Bibb | T65: 480 | Z65: Bangor | AA65: 161 | AB65: 108 | AF65: Atlantic Technical College | AG65: 40 | AH65: 0 | AL65: Bibb | AM65: 1180 | AN65: 480 | AT65: 107664
A66: Atlantis University | B66: 1 | H66: Big Horn | I66: 10 | K66: Atlantis University | L66: 0 | S66: Big Horn | T66: 0 | Z66: Banner Elk | AA66: 84 | AB66: 47 | AF66: Atlantis University | AG66: 1 | AH66: 0 | AL66: Big Horn | AM66: 10 | AN66: 0 | AT66: 107743
A67: Auburn University | B67: 2742 | H67: Black Hawk | I67: 1031 | K67: Auburn University | L67: 567 | S67: Black Hawk | T67: 160 | Z67: Barbourville | AA67: 78 | AB67: 24 | AF67: Auburn University | AG67: 2742 | AH67: 567 | AL67: Black Hawk | AM67: 1031 | AN67: 160 | AT67: 107974
A68: Auburn University at Montgomery | B68: 220 | H68: Blair | I68: 339 | K68: Auburn University at Montgomery | L68: 80 | S68: Blair | T68: 45 | Z68: Barnesville | AA68: 57 | AB68: 8 | AF68: Auburn University at Montgomery | AG68: 220 | AH68: 80 | AL68: Blair | AM68: 339 | AN68: 45 | AT68: 107983
A69: Augsburg University | B69: 253 | H69: Blount | I69: 26 | K69: Augsburg University | L69: 102 | S69: Blount | T69: 24 | Z69: Batavia | AA69: 53 | AB69: 25 | AF69: Augsburg University | AG69: 253 | AH69: 102 | AL69: Blount | AM69: 26 | AN69: 24 | AT69: 108092
A70: Augusta University | B70: 806 | H70: Blue Earth | I70: 754 | K70: Augusta University | L70: 385 | S70: Blue Earth | T70: 204 | Z70: Batesville | AA70: 116 | AB70: 88 | AF70: Augusta University | AG70: 806 | AH70: 385 | AL70: Blue Earth | AM70: 754 | AN70: 204 | AT70: 108232
A71: Augustana College | B71: 260 | H71: Bolivar | I71: 263 | K71: Augustana College | L71: 126 | S71: Bolivar | T71: 79 | Z71: Baton Rouge | AA71: 2832 | AB71: 920 | AF71: Augustana College | AG71: 260 | AH71: 126 | AL71: Bolivar | AM71: 263 | AN71: 79 | AT71: 109350
A72: Augustana University | B72: 375 | H72: Bond | I72: 205 | K72: Augustana University | L72: 43 | S72: Bond | T72: 101 | Z72: Bayamon | AA72: 0 | AB72: 0 | AF72: Augustana University | AG72: 375 | AH72: 43 | AL72: Bond | AM72: 205 | AN72: 101 | AT72: 109785
A73: Aurora University | B73: 166 | H73: Boone | I73: 3384 | K73: Aurora University | L73: 65 | S73: Boone | T73: 324 | Z73: Beaumont | AA73: 390 | AB73: 88 | AF73: Aurora University | AG73: 166 | AH73: 65 | AL73: Boone | AM73: 3384 | AN73: 324 | AT73: 109819
... A739: Knox College | B739: 78 | H739: Grand Total | I739: 708173 | K739: Knox College | L739: 30 | S739: Grand Total | T739: 270827 | Z739: New Britain | AA739: 332 | AB739: 171 | AF739: Knox College | AG739: 78 | AH739: 30 | AL739: Grand Total | AM739: 708173 | AN739: 270827 | AT739: 173142
A740: Kutztown University | B740: 535 | K740: Kutztown University | L740: 119 | Z740: New Brunswick | AA740: 1938 | AB740: 1307 | AF740: Kutztown University | AG740: 535 | AH740: 119 | AT740: 173160
A741: Kuyper College | B741: 6 | K741: Kuyper College | L741: 0 | Z741: New Castle | AA741: 0 | AB741: 0 | AF741: Kuyper College | AG741: 6 | AH741: 0 | AT741: 173203
A742: La Roche University | B742: 38 | K742: La Roche University | L742: 29 | Z742: New Concord | AA742: 171 | AB742: 107 | AF742: La Roche University | AG742: 38 | AH742: 29 | AT742: 173258
A743: La Salle University | B743: 188 | K743: La Salle University | L743: 143 | Z743: New Haven | AA743: 1458 | AB743: 838 | AF743: La Salle University | AG743: 188 | AH743: 143 | AT743: 173300
A744: Labette Community College | B744: 5 | K744: Labette Community College | L744: 0 | Z744: New Kensington | AA744: 17 | AB744: 9 | AF744: Labette Community College | AG744: 5 | AH744: 0 | AT744: 173328
A745: Lafayette College | B745: 489 | K745: Lafayette College | L745: 453 | Z745: New London | AA745: 333 | AB745: 174 | AF745: Lafayette College | AG745: 489 | AH745: 453 | AT745: 173416
A746: LaGrange College | B746: 87 | K746: LaGrange College | L746: 35 | Z746: New Orleans | AA746: 3354 | AB746: 1284 | AF746: LaGrange College | AG746: 87 | AH746: 35 | AT746: 173452
A747: Lake Erie College | B747: 243 | K747: Lake Erie College | L747: 196 | Z747: New Paltz | AA747: 440 | AB747: 331 | AF747: Lake Erie College | AG747: 243 | AH747: 196 | AT747: 173461
A748: Lake Forest College | B748: 80 | K748: Lake Forest College | L748: 72 | Z748: New Philadelphia | AA748: 3 | AB748: 0 | AF748: Lake Forest College | AG748: 80 | AH748: 72 | AT748: 173559
A749: Lake Land College | B749: 133 | K749: Lake Land College | L749: 39 | Z749: New Port Richey | AA749: 117 | AB749: 49 | AF749: Lake Land College | AG749: 133 | AH749: 39 | AT749: 173638
...

Sheet Analysis Charts

Sheet Analysis Report
